Workbook

Sheet Master Catalogue
A1: Faction | B1: Subfaction/Chapter | C1: Battlefield Role | D1: Unit Type | E1: Unit Name | F1: Models | G1: Keywords / Tags | H1: Owned? | I1: Built? | J1: Paint Status | K1: Wishlist Priority | L1: Points | M1: Notes | N1: Verification Status | O1: Source URL
A2: Salamanders | B2: Salamanders | C2: Infantry / Other | D2: Infantry | E2: Adrax Agatone | F2: 1 model | G2: Infantry | L2: 85 | N2: Matched to Munitorum Field Manual v2.3 | O2: Uploaded PDF: Munitorum Field Manual v2.3 / March 2025, p.31
A3: Space Marines | B3: Space Marines | C3: Infantry / Other | D3: Infantry | E3: Aggressor Squad | F3: 3 models | G3: Infantry | L3: 120 | M3: Points options: 3 models = 120 pts; 6 models = 240 pts | N3: Matched to Munitorum Field Manual v2.3 | O3: Uploaded PDF: Munitorum Field Manual v2.3 / March 2025, p.31
A4: Space Marines | B4: Space Marines | C4: Character | D4: Character | E4: Ancient | F4: 1 model | G4: Character | L4: 50 | N4: Matched to Munitorum Field Manual v2.3 | O4: Uploaded PDF: Munitorum Field Manual v2.3 / March 2025, p.31
A5: Space Marines | B5: Space Marines | C5: Character | D5: Character | E5: Apothecary | F5: 1 model | G5: Character | L5: 50 | N5: Matched to Munitorum Field Manual v2.3 | O5: Uploaded PDF: Munitorum Field Manual v2.3 / March 2025, p.31
A6: Space Marines | B6: Space Marines | C6: Character | D6: Character | E6: Apothecary Biologis | F6: 1 model | G6: Character | L6: 70 | N6: Matched to Munitorum Field Manual v2.3 | O6: Uploaded PDF: Munitorum Field Manual v2.3 / March 2025, p.31
A7: Space Marines | B7: Space Marines | C7: Battleline / Core | D7: Infantry | E7: Assault Intercessor Squad | F7: 5 models | G7: Infantry | L7: 75 | M7: Points options: 5 models = 75 pts; 10 models = 150 pts | N7: Matched to Munitorum Field Manual v2.3 | O7: Uploaded PDF: Munitorum Field Manual v2.3 / March 2025, p.31
A8: Space Marines | B8: Space Marines | C8: Infantry / Other | D8: Infantry | E8: Assault Intercessors with Jump Packs | F8: 5 models | G8: Infantry | L8: 90 | M8: Points options: 5 models = 90 pts; 10 models = 160 pts | N8: Matched to Munitorum Field Manual v2.3 | O8: Uploaded PDF: Munitorum Field Manual v2.3 / March 2025, p.31
A9: Space Marines | B9: Space Marines | C9: Vehicle / Support | D9: Walker / Battlesuit | E9: Ballistus Dreadnought | F9: 1 model | G9: Walker / Battlesuit | L9: 140 | N9: Matched to Munitorum Field Manual v2.3 | O9: Uploaded PDF: Munitorum Field Manual v2.3 / March 2025, p.31
A10: Space Marines | B10: Space Marines | C10: Character | D10: Character | E10: Bladeguard Ancient | F10: 1 model | G10: Character | L10: 45 | N10: Matched to Munitorum Field Manual v2.3 | O10: Uploaded PDF: Munitorum Field Manual v2.3 / March 2025, p.31
A11: Space Marines | B11: Space Marines | C11: Infantry / Other | D11: Infantry | E11: Bladeguard Veteran Squad | F11: 3 models | G11: Infantry | L11: 80 | M11: Points options: 3 models = 80 pts; 6 models = 160 pts | N11: Matched to Munitorum Field Manual v2.3 | O11: Uploaded PDF: Munitorum Field Manual v2.3 / March 2025, p.31
A12: Space Marines | B12: Space Marines | C12: Vehicle / Support | D12: Walker / Battlesuit | E12: Brutalis Dreadnought | F12: 1 model | G12: Walker / Battlesuit | L12: 160 | N12: Matched to Munitorum Field Manual v2.3 | O12: Uploaded PDF: Munitorum Field Manual v2.3 / March 2025, p.31
A13: Space Marines | B13: Space Marines | C13: Character | D13: Character | E13: Captain | F13: 1 model | G13: Character | L13: 80 | N13: Matched to Munitorum Field Manual v2.3 | O13: Uploaded PDF: Munitorum Field Manual v2.3 / March 2025, p.31
A14: Space Marines | B14: Space Marines | C14: Character | D14: Character | E14: Captain in Gravis Armour | F14: 1 model | G14: Character | L14: 80 | N14: Matched to Munitorum Field Manual v2.3 | O14: Uploaded PDF: Munitorum Field Manual v2.3 / March 2025, p.31
A15: Space Marines | B15: Space Marines | C15: Character | D15: Character | E15: Captain in Phobos Armour | F15: 1 model | G15: Character | L15: 70 | N15: Matched to Munitorum Field Manual v2.3 | O15: Uploaded PDF: Munitorum Field Manual v2.3 / March 2025, p.31
A16: Space Marines | B16: Space Marines | C16: Character | D16: Character | E16: Captain in Terminator Armour | F16: 1 model | G16: Character | L16: 95 | N16: Matched to Munitorum Field Manual v2.3 | O16: Uploaded PDF: Munitorum Field Manual v2.3 / March 2025, p.31
A17: Ultramarines | B17: Ultramarines | C17: Character | D17: Character | E17: Captain Sicarius | F17: 1 model | G17: Character | L17: 85 | N17: Matched to Munitorum Field Manual v2.3 | O17: Uploaded PDF: Munitorum Field Manual v2.3 / March 2025, p.31
A18: Space Marines | B18: Space Marines | C18: Character | D18: Character | E18: Chaplain | F18: 1 model | G18: Character | L18: 60 | N18: Matched to Munitorum Field Manual v2.3 | O18: Uploaded PDF: Munitorum Field Manual v2.3 / March 2025, p.31
A19: Space Marines | B19: Space Marines | C19: Character | D19: Character | E19: Chaplain in Terminator Armour | F19: 1 model | G19: Character | L19: 75 | N19: Matched to Munitorum Field Manual v2.3 | O19: Uploaded PDF: Munitorum Field Manual v2.3 / March 2025, p.31
A20: Space Marines | B20: Space Marines | C20: Character | D20: Character | E20: Chaplain on Bike | F20: 1 model | G20: Character | L20: 75 | N20: Matched to Munitorum Field Manual v2.3 | O20: Uploaded PDF: Munitorum Field Manual v2.3 / March 2025, p.31
A21: Space Marines | B21: Space Marines | C21: Infantry / Other | D21: Infantry | E21: Company Heroes | F21: 4 models | G21: Infantry | L21: 105 | N21: Matched to Munitorum Field Manual v2.3 | O21: Uploaded PDF: Munitorum Field Manual v2.3 / March 2025, p.31
A22: Imperial Fists | B22: Imperial Fists | C22: Infantry / Other | D22: Infantry | E22: Darnath Lysander | F22: 1 model | G22: Infantry | L22: 100 | N22: Matched to Munitorum Field Manual v2.3 | O22: Uploaded PDF: Munitorum Field Manual v2.3 / March 2025, p.31
A23: Space Marines | B23: Space Marines | C23: Infantry / Other | D23: Infantry | E23: Desolation Squad | F23: 5 models | G23: Infantry | L23: 200 | N23: Matched to Munitorum Field Manual v2.3 | O23: Uploaded PDF: Munitorum Field Manual v2.3 / March 2025, p.31
A24: Space Marines | B24: Space Marines | C24: Infantry / Other | D24: Infantry | E24: Devastator Squad | F24: 5 models | G24: Infantry | L24: 120 | M24: Points options: 5 models = 120 pts; 10 models = 200 pts | N24: Matched to Munitorum Field Manual v2.3 | O24: Uploaded PDF: Munitorum Field Manual v2.3 / March 2025, p.31
A25: Space Marines | B25: Space Marines | C25: Infantry / Other | D25: Infantry | E25: Eliminator Squad | F25: 3 models | G25: Infantry | L25: 85 | N25: Matched to Munitorum Field Manual v2.3 | O25: Uploaded PDF: Munitorum Field Manual v2.3 / March 2025, p.31
A26: Space Marines | B26: Space Marines | C26: Infantry / Other | D26: Infantry | E26: Eradicator Squad | F26: 3 models | G26: Infantry | L26: 100 | M26: Points options: 3 models = 100 pts; 6 models = 200 pts | N26: Matched to Munitorum Field Manual v2.3 | O26: Uploaded PDF: Munitorum Field Manual v2.3 / March 2025, p.31
A27: Space Marines | B27: Space Marines | C27: Vehicle / Support | D27: Vehicle | E27: Gladiator Lancer | F27: 1 model | G27: Vehicle | L27: 160 | N27: Matched to Munitorum Field Manual v2.3 | O27: Uploaded PDF: Munitorum Field Manual v2.3 / March 2025, p.31
A28: Space Marines | B28: Space Marines | C28: Vehicle / Support | D28: Vehicle | E28: Gladiator Reaper | F28: 1 model | G28: Vehicle | L28: 160 | N28: Matched to Munitorum Field Manual v2.3 | O28: Uploaded PDF: Munitorum Field Manual v2.3 / March 2025, p.31
A29: Space Marines | B29: Space Marines | C29: Vehicle / Support | D29: Vehicle | E29: Gladiator Valiant | F29: 1 model | G29: Vehicle | L29: 160 | N29: Matched to Munitorum Field Manual v2.3 | O29: Uploaded PDF: Munitorum Field Manual v2.3 / March 2025, p.31
A30: Space Marines | B30: Space Marines | C30: Vehicle / Support | D30: Vehicle | E30: Hammerfall Bunker | F30: 1 model | G30: Vehicle | L30: 175 | N30: Matched to Munitorum Field Manual v2.3 | O30: Uploaded PDF: Munitorum Field Manual v2.3 / March 2025, p.31
A31: Space Marines | B31: Space Marines | C31: Battleline / Core | D31: Infantry | E31: Heavy Intercessor Squad | F31: 5 models | G31: Infantry | L31: 110 | M31: Points options: 5 models = 110 pts; 10 models = 220 pts | N31: Matched to Munitorum Field Manual v2.3 | O31: Uploaded PDF: Munitorum Field Manual v2.3 / March 2025, p.31
A32: Space Marines | B32: Space Marines | C32: Infantry / Other | D32: Infantry | E32: Hellblaster Squad | F32: 5 models | G32: Infantry | L32: 115 | M32: Points options: 5 models = 115 pts; 10 models = 230 pts | N32: Matched to Munitorum Field Manual v2.3 | O32: Uploaded PDF: Munitorum Field Manual v2.3 / March 2025, p.31
A33: Space Marines | B33: Space Marines | C33: Vehicle / Support | D33: Vehicle | E33: Impulsor | F33: 1 model | G33: Vehicle | L33: 80 | N33: Matched to Munitorum Field Manual v2.3 | O33: Uploaded PDF: Munitorum Field Manual v2.3 / March 2025, p.31
A34: Space Marines | B34: Space Marines | C34: Infantry / Other | D34: Infantry | E34: Inceptor Squad | F34: 3 models | G34: Infantry | L34: 120 | M34: Points options: 3 models = 120 pts; 6 models = 240 pts | N34: Matched to Munitorum Field Manual v2.3 | O34: Uploaded PDF: Munitorum Field Manual v2.3 / March 2025, p.31
A35: Space Marines | B35: Space Marines | C35: Infantry / Other | D35: Infantry | E35: Incursor Squad | F35: 5 models | G35: Infantry | L35: 80 | M35: Points options: 5 models = 80 pts; 10 models = 160 pts | N35: Matched to Munitorum Field Manual v2.3 | O35: Uploaded PDF: Munitorum Field Manual v2.3 / March 2025, p.31
A36: Space Marines | B36: Space Marines | C36: Infantry / Other | D36: Infantry | E36: Infernus Squad | F36: 5 models | G36: Infantry | L36: 90 | M36: Points options: 5 models = 90 pts; 10 models = 180 pts | N36: Matched to Munitorum Field Manual v2.3 | O36: Uploaded PDF: Munitorum Field Manual v2.3 / March 2025, p.31
A37: Space Marines | B37: Space Marines | C37: Infantry / Other | D37: Infantry | E37: Infiltrator Squad | F37: 5 models | G37: Infantry | L37: 100 | M37: Points options: 5 models = 100 pts; 10 models = 200 pts | N37: Matched to Munitorum Field Manual v2.3 | O37: Uploaded PDF: Munitorum Field Manual v2.3 / March 2025, p.31
A38: Space Marines | B38: Space Marines | C38: Infantry / Other | D38: Mounted / Bike | E38: Invader ATV | F38: 1 model | G38: Mounted / Bike | L38: 60 | N38: Matched to Munitorum Field Manual v2.3 | O38: Uploaded PDF: Munitorum Field Manual v2.3 / March 2025, p.31
A39: Space Marines | B39: Space Marines | C39: Vehicle / Support | D39: Walker / Battlesuit | E39: Invictor Tactical Warsuit | F39: 1 model | G39: Walker / Battlesuit | L39: 125 | N39: Matched to Munitorum Field Manual v2.3 | O39: Uploaded PDF: Munitorum Field Manual v2.3 / March 2025, p.31
A40: Space Marines | B40: Space Marines | C40: Infantry / Other | D40: Infantry | E40: Judiciar | F40: 1 model | G40: Infantry | L40: 70 | N40: Matched to Munitorum Field Manual v2.3 | O40: Uploaded PDF: Munitorum Field Manual v2.3 / March 2025, p.31
...

Sheet Lists
A1: Factions | B1: Unit Types | C1: Paint Status
A2: Adepta Sororitas | B2: Aircraft | C2: Unpainted
A3: Adeptus Custodes | B3: Beast / Swarm | C3: Primed
A4: Adeptus Mechanicus | B4: Character | C4: Battle Ready
A5: Aeldari | B5: Infantry | C5: Parade Ready
A6: Astra Militarum | B6: Monster | C6: Needs Rework
A7: Black Templars | B7: Mounted / Bike
A8: Blood Angels | B8: Super-heavy Vehicle/Monster
A9: Chaos Daemons | B9: Vehicle
A10: Chaos Knights | B10: Walker / Battlesuit
A11: Chaos Space Marines
A12: Dark Angels
A13: Death Guard
A14: Deathwatch
A15: Drukhari
A16: Emperor's Children
A17: Genestealer Cults
A18: Grey Knights
A19: Harlequins
A20: Imperial Agents
A21: Imperial Knights
A22: Leagues of Votann
... A30: World Eaters

Sheet Dashboard
A1: Warhammer 40,000 10th Edition Catalogue Workbook
A3: Total catalogue rows | B3: =COUNTA('Master Catalogue'!E2:E820) | D3: Faction | E3: Rows | F3: Owned
A4: Factions included | B4: =COUNTA(Lists!A2:A30) | D4: Adepta Sororitas | E4: =COUNTIF('Master Catalogue'!A:A,D4) | F4: =COUNTIFS('Master Catalogue'!A:A,D4,'Master Catalogue'!H:H,"Yes")
A5: Owned rows | B5: =COUNTIF('Master Catalogue'!H2:H820,"Yes") | D5: Adeptus Custodes | E5: =COUNTIF('Master Catalogue'!A:A,D5) | F5: =COUNTIFS('Master Catalogue'!A:A,D5,'Master Catalogue'!H:H,"Yes")
A6: Battle Ready / Parade Ready | B6: =COUNTIF('Master Catalogue'!J2:J820,"Battle Ready")+COUNTIF('Master Catalogue'!J2:J820,"Parade Ready") | D6: Adeptus Mechanicus | E6: =COUNTIF('Master Catalogue'!A:A,D6) | F6: =COUNTIFS('Master Catalogue'!A:A,D6,'Master Catalogue'!H:H,"Yes")
A7: Wishlist High | B7: =COUNTIF('Master Catalogue'!K2:K820,"High") | D7: Aeldari | E7: =COUNTIF('Master Catalogue'!A:A,D7) | F7: =COUNTIFS('Master Catalogue'!A:A,D7,'Master Catalogue'!H:H,"Yes")
A8: Points entered | B8: =COUNT('Master Catalogue'!L2:L820) | D8: Astra Militarum | E8: =COUNTIF('Master Catalogue'!A:A,D8) | F8: =COUNTIFS('Master Catalogue'!A:A,D8,'Master Catalogue'!H:H,"Yes")
D9: Black Templars | E9: =COUNTIF('Master Catalogue'!A:A,D9) | F9: =COUNTIFS('Master Catalogue'!A:A,D9,'Master Catalogue'!H:H,"Yes")
D10: Blood Angels | E10: =COUNTIF('Master Catalogue'!A:A,D10) | F10: =COUNTIFS('Master Catalogue'!A:A,D10,'Master Catalogue'!H:H,"Yes")
D11: Chaos Daemons | E11: =COUNTIF('Master Catalogue'!A:A,D11) | F11: =COUNTIFS('Master Catalogue'!A:A,D11,'Master Catalogue'!H:H,"Yes")
D12: Chaos Knights | E12: =COUNTIF('Master Catalogue'!A:A,D12) | F12: =COUNTIFS('Master Catalogue'!A:A,D12,'Master Catalogue'!H:H,"Yes")
D13: Chaos Space Marines | E13: =COUNTIF('Master Catalogue'!A:A,D13) | F13: =COUNTIFS('Master Catalogue'!A:A,D13,'Master Catalogue'!H:H,"Yes")
D14: Dark Angels | E14: =COUNTIF('Master Catalogue'!A:A,D14) | F14: =COUNTIFS('Master Catalogue'!A:A,D14,'Master Catalogue'!H:H,"Yes")
D15: Death Guard | E15: =COUNTIF('Master Catalogue'!A:A,D15) | F15: =COUNTIFS('Master Catalogue'!A:A,D15,'Master Catalogue'!H:H,"Yes")
D16: Deathwatch | E16: =COUNTIF('Master Catalogue'!A:A,D16) | F16: =COUNTIFS('Master Catalogue'!A:A,D16,'Master Catalogue'!H:H,"Yes")
D17: Drukhari | E17: =COUNTIF('Master Catalogue'!A:A,D17) | F17: =COUNTIFS('Master Catalogue'!A:A,D17,'Master Catalogue'!H:H,"Yes")
D18: Emperor's Children | E18: =COUNTIF('Master Catalogue'!A:A,D18) | F18: =COUNTIFS('Master Catalogue'!A:A,D18,'Master Catalogue'!H:H,"Yes")
D19: Genestealer Cults | E19: =COUNTIF('Master Catalogue'!A:A,D19) | F19: =COUNTIFS('Master Catalogue'!A:A,D19,'Master Catalogue'!H:H,"Yes")
D20: Grey Knights | E20: =COUNTIF('Master Catalogue'!A:A,D20) | F20: =COUNTIFS('Master Catalogue'!A:A,D20,'Master Catalogue'!H:H,"Yes")
... D32: World Eaters | E32: =COUNTIF('Master Catalogue'!A:A,D32) | F32: =COUNTIFS('Master Catalogue'!A:A,D32,'Master Catalogue'!H:H,"Yes")

Sheet Army Builder
A1: Roster Name | B1: Faction | C1: Unit Name | D1: Quantity | E1: Points Each | F1: Line Total | G1: Role | H1: Notes | J1: Army Total | K1: =SUM(F2:F201)
D2: 1 | E2: =IFERROR(XLOOKUP(C2,'Master Catalogue'!$E:$E,'Master Catalogue'!$L:$L),"") | F2: =IF(E2="","",D2*E2) | J2: Target | K2: 2000
D3: 1 | E3: =IFERROR(XLOOKUP(C3,'Master Catalogue'!$E:$E,'Master Catalogue'!$L:$L),"") | F3: =IF(E3="","",D3*E3) | J3: Remaining | K3: =K2-K1
D4: 1 | E4: =IFERROR(XLOOKUP(C4,'Master Catalogue'!$E:$E,'Master Catalogue'!$L:$L),"") | F4: =IF(E4="","",D4*E4) | J4: Rows used | K4: =COUNTA(C2:C201)
D5: 1 | E5: =IFERROR(XLOOKUP(C5,'Master Catalogue'!$E:$E,'Master Catalogue'!$L:$L),"") | F5: =IF(E5="","",D5*E5)
D6: 1 | E6: =IFERROR(XLOOKUP(C6,'Master Catalogue'!$E:$E,'Master Catalogue'!$L:$L),"") | F6: =IF(E6="","",D6*E6)
D7: 1 | E7: =IFERROR(XLOOKUP(C7,'Master Catalogue'!$E:$E,'Master Catalogue'!$L:$L),"") | F7: =IF(E7="","",D7*E7)
D8: 1 | E8: =IFERROR(XLOOKUP(C8,'Master Catalogue'!$E:$E,'Master Catalogue'!$L:$L),"") | F8: =IF(E8="","",D8*E8)
D9: 1 | E9: =IFERROR(XLOOKUP(C9,'Master Catalogue'!$E:$E,'Master Catalogue'!$L:$L),"") | F9: =IF(E9="","",D9*E9)
D10: 1 | E10: =IFERROR(XLOOKUP(C10,'Master Catalogue'!$E:$E,'Master Catalogue'!$L:$L),"") | F10: =IF(E10="","",D10*E10)
D11: 1 | E11: =IFERROR(XLOOKUP(C11,'Master Catalogue'!$E:$E,'Master Catalogue'!$L:$L),"") | F11: =IF(E11="","",D11*E11)
D12: 1 | E12: =IFERROR(XLOOKUP(C12,'Master Catalogue'!$E:$E,'Master Catalogue'!$L:$L),"") | F12: =IF(E12="","",D12*E12)
D13: 1 | E13: =IFERROR(XLOOKUP(C13,'Master Catalogue'!$E:$E,'Master Catalogue'!$L:$L),"") | F13: =IF(E13="","",D13*E13)
D14: 1 | E14: =IFERROR(XLOOKUP(C14,'Master Catalogue'!$E:$E,'Master Catalogue'!$L:$L),"") | F14: =IF(E14="","",D14*E14)
D15: 1 | E15: =IFERROR(XLOOKUP(C15,'Master Catalogue'!$E:$E,'Master Catalogue'!$L:$L),"") | F15: =IF(E15="","",D15*E15)
D16: 1 | E16: =IFERROR(XLOOKUP(C16,'Master Catalogue'!$E:$E,'Master Catalogue'!$L:$L),"") | F16: =IF(E16="","",D16*E16)
... D201: 1 | E201: =IFERROR(XLOOKUP(C201,'Master Catalogue'!$E:$E,'Master Catalogue'!$L:$L),"") | F201: =IF(E201="","",D201*E201)

Sheet Collection Tracker
A1: Faction | B1: Unit Name | C1: Owned Qty | D1: Built Qty | E1: Painted Qty | F1: Target Qty | G1: Gap
A2: Space Marines | B2: Adrax Agatone | G2: =IF(F2="","",F2-C2)
A3: Space Marines | B3: Aggressor Squad | G3: =IF(F3="","",F3-C3)
A4: Space Marines | B4: Ancient | G4: =IF(F4="","",F4-C4)
A5: Space Marines | B5: Apothecary | G5: =IF(F5="","",F5-C5)
A6: Space Marines | B6: Apothecary Biologis | G6: =IF(F6="","",F6-C6)
A7: Space Marines | B7: Assault Intercessor Squad | G7: =IF(F7="","",F7-C7)
A8: Space Marines | B8: Assault Intercessors with Jump Packs | G8: =IF(F8="","",F8-C8)
A9: Space Marines | B9: Ballistus Dreadnought | G9: =IF(F9="","",F9-C9)
A10: Space Marines | B10: Bladeguard Ancient | G10: =IF(F10="","",F10-C10)
A11: Space Marines | B11: Bladeguard Veteran Squad | G11: =IF(F11="","",F11-C11)
A12: Space Marines | B12: Brutalis Dreadnought | G12: =IF(F12="","",F12-C12)
A13: Space Marines | B13: Captain | G13: =IF(F13="","",F13-C13)
... A820: Leagues of Votann | B820: Ûthar the Destined | G820: =IF(F820="","",F820-C820)

Sheet Adepta Sororitas
A1: Faction | B1: Subfaction/Chapter | C1: Battlefield Role | D1: Unit Type | E1: Unit Name | F1: Models | G1: Keywords / Tags | H1: Owned? | I1: Built? | J1: Paint Status | K1: Wishlist Priority | L1: Points | M1: Notes | N1: Verification Status | O1: Source URL
A2: Adepta Sororitas | C2: Infantry / Other | D2: Infantry | E2: Aestred Thurga and Agathae Dolan | F2: 2 models | G2: Infantry | L2: 85 | N2: Matched to Munitorum Field Manual v2.3 | O2: Uploaded PDF: Munitorum Field Manual v2.3 / March 2025, p.2
A3: Adepta Sororitas | C3: Infantry / Other | D3: Infantry | E3: Arco-flagellants | F3: 3 models | G3: Infantry | L3: 45 | M3: Points options: 3 models = 45 pts; 10 models = 140 pts | N3: Matched to Munitorum Field Manual v2.3 | O3: Uploaded PDF: Munitorum Field Manual v2.3 / March 2025, p.2
A4: Adepta Sororitas | C4: Battleline / Core | D4: Infantry | E4: Battle Sisters Squad | F4: 10 models | G4: Infantry | L4: 105 | N4: Matched to Munitorum Field Manual v2.3 | O4: Uploaded PDF: Munitorum Field Manual v2.3 / March 2025, p.2
A5: Adepta Sororitas | C5: Character | D5: Character | E5: Canoness | F5: 1 model | G5: Character | L5: 50 | N5: Matched to Munitorum Field Manual v2.3 | O5: Uploaded PDF: Munitorum Field Manual v2.3 / March 2025, p.2
A6: Adepta Sororitas | C6: Vehicle / Support | D6: Vehicle | E6: Castigator | F6: 1 model | G6: Vehicle | L6: 170 | N6: Matched to Munitorum Field Manual v2.3 | O6: Uploaded PDF: Munitorum Field Manual v2.3 / March 2025, p.2
A7: Adepta Sororitas | C7: Infantry / Other | D7: Infantry | E7: Celestian Sacresants | F7: 5 models | G7: Infantry | L7: 70 | M7: Points options: 5 models = 70 pts; 10 models = 130 pts | N7: Matched to Munitorum Field Manual v2.3 | O7: Uploaded PDF: Munitorum Field Manual v2.3 / March 2025, p.2
A8: Adepta Sororitas | C8: Infantry / Other | D8: Infantry | E8: Daemonifuge | F8: 2 models | G8: Infantry | L8: 85 | N8: Matched to Munitorum Field Manual v2.3 | O8: Uploaded PDF: Munitorum Field Manual v2.3 / March 2025, p.2
A9: Adepta Sororitas | C9: Character | D9: Character | E9: Death Cult Assassins | G9: Character | M9: No matching points entry found in uploaded PDF; verify unit name/current support. | N9: Not found in uploaded PDF | O9: Uploaded PDF: Munitorum Field Manual v2.3 / March 2025
A10: Adepta Sororitas | C10: Infantry / Other | D10: Infantry | E10: Dialogus | F10: 1 model | G10: Infantry | L10: 40 | N10: Matched to Munitorum Field Manual v2.3 | O10: Uploaded PDF: Munitorum Field Manual v2.3 / March 2025, p.2
A11: Adepta Sororitas | C11: Infantry / Other | D11: Infantry | E11: Dogmata | F11: 1 model | G11: Infantry | L11: 45 | N11: Matched to Munitorum Field Manual v2.3 | O11: Uploaded PDF: Munitorum Field Manual v2.3 / March 2025, p.2
A12: Adepta Sororitas | C12: Infantry / Other | D12: Infantry | E12: Dominion Squad | F12: 10 models | G12: Infantry | L12: 115 | N12: Matched to Munitorum Field Manual v2.3 | O12: Uploaded PDF: Munitorum Field Manual v2.3 / March 2025, p.2
A13: Adepta Sororitas | C13: Vehicle / Support | D13: Vehicle | E13: Exorcist | F13: 1 model | G13: Vehicle | L13: 210 | N13: Matched to Munitorum Field Manual v2.3 | O13: Uploaded PDF: Munitorum Field Manual v2.3 / March 2025, p.2
A14: Adepta Sororitas | C14: Infantry / Other | D14: Infantry | E14: Hospitaller | F14: 1 model | G14: Infantry | L14: 50 | N14: Matched to Munitorum Field Manual v2.3 | O14: Uploaded PDF: Munitorum Field Manual v2.3 / March 2025, p.2
A15: Adepta Sororitas | C15: Infantry / Other | D15: Infantry | E15: Imagifier | F15: 1 model | G15: Infantry | L15: 65 | N15: Matched to Munitorum Field Manual v2.3 | O15: Uploaded PDF: Munitorum Field Manual v2.3 / March 2025, p.2
A16: Adepta Sororitas | C16: Vehicle / Support | D16: Vehicle | E16: Immolator | F16: 1 model | G16: Vehicle | L16: 125 | N16: Matched to Munitorum Field Manual v2.3 | O16: Uploaded PDF: Munitorum Field Manual v2.3 / March 2025, p.2
A17: Adepta Sororitas | C17: Infantry / Other | D17: Infantry | E17: Junith Eruita | F17: 1 model | G17: Infantry | L17: 90 | N17: Matched to Munitorum Field Manual v2.3 | O17: Uploaded PDF: Munitorum Field Manual v2.3 / March 2025, p.2
A18: Adepta Sororitas | C18: Character | D18: Character | E18: Ministorum Priest | F18: 1 model | G18: Character | L18: 50 | N18: Matched to Munitorum Field Manual v2.3 | O18: Uploaded PDF: Munitorum Field Manual v2.3 / March 2025, p.2
A19: Adepta Sororitas | C19: Infantry / Other | D19: Infantry | E19: Missionary | G19: Infantry | M19: No matching points entry found in uploaded PDF; verify unit name/current support. | N19: Not found in uploaded PDF | O19: Uploaded PDF: Munitorum Field Manual v2.3 / March 2025
A20: Adepta Sororitas | C20: Infantry / Other | D20: Infantry | E20: Mortifiers | F20: 1 model | G20: Infantry | L20: 70 | M20: Points options: 1 model = 70 pts; 2 models = 140 pts | N20: Matched to Munitorum Field Manual v2.3 | O20: Uploaded PDF: Munitorum Field Manual v2.3 / March 2025, p.2
A21: Adepta Sororitas | C21: Infantry / Other | D21: Infantry | E21: Morvenn Vahl | F21: 1 model | G21: Infantry, Epic Hero | L21: 170 | N21: Matched to Munitorum Field Manual v2.3 | O21: Uploaded PDF: Munitorum Field Manual v2.3 / March 2025, p.2
A22: Adepta Sororitas | C22: Character | D22: Character | E22: Palatine | F22: 1 model | G22: Character | L22: 50 | N22: Matched to Munitorum Field Manual v2.3 | O22: Uploaded PDF: Munitorum Field Manual v2.3 / March 2025, p.2
A23: Adepta Sororitas | C23: Vehicle / Support | D23: Walker / Battlesuit | E23: Paragon Warsuits | F23: 3 models | G23: Walker / Battlesuit | L23: 220 | N23: Matched to Munitorum Field Manual v2.3 | O23: Uploaded PDF: Munitorum Field Manual v2.3 / March 2025, p.2
A24: Adepta Sororitas | C24: Infantry / Other | D24: Infantry | E24: Penitent Engines | F24: 1 model | G24: Infantry | L24: 75 | M24: Points options: 1 model = 75 pts; 2 models = 150 pts | N24: Matched to Munitorum Field Manual v2.3 | O24: Uploaded PDF: Munitorum Field Manual v2.3 / March 2025, p.2
A25: Adepta Sororitas | C25: Character | D25: Character | E25: Preacher | G25: Character | M25: No matching points entry found in uploaded PDF; verify unit name/current support. | N25: Not found in uploaded PDF | O25: Uploaded PDF: Munitorum Field Manual v2.3 / March 2025
A26: Adepta Sororitas | C26: Infantry / Other | D26: Infantry | E26: Retributor Squad | F26: 5 models | G26: Infantry | L26: 125 | N26: Matched to Munitorum Field Manual v2.3 | O26: Uploaded PDF: Munitorum Field Manual v2.3 / March 2025, p.2
A27: Adepta Sororitas | C27: Vehicle / Support | D27: Vehicle | E27: Rhino | G27: Vehicle | M27: No matching points entry found in uploaded PDF; verify unit name/current support. | N27: Not found in uploaded PDF | O27: Uploaded PDF: Munitorum Field Manual v2.3 / March 2025
A28: Adepta Sororitas | C28: Infantry / Other | D28: Infantry | E28: Saint Celestine | F28: 3 models | G28: Infantry, Epic Hero | L28: 160 | N28: Matched to Munitorum Field Manual v2.3 | O28: Uploaded PDF: Munitorum Field Manual v2.3 / March 2025, p.2
A29: Adepta Sororitas | C29: Infantry / Other | D29: Infantry | E29: Seraphim Squad | F29: 5 models | G29: Infantry | L29: 85 | M29: Points options: 5 models = 85 pts; 10 models = 170 pts | N29: Matched to Munitorum Field Manual v2.3 | O29: Uploaded PDF: Munitorum Field Manual v2.3 / March 2025, p.2
A30: Adepta Sororitas | C30: Infantry / Other | D30: Infantry | E30: Triumph of Saint Katherine | F30: 1 model | G30: Infantry | L30: 250 | N30: Matched to Munitorum Field Manual v2.3 | O30: Uploaded PDF: Munitorum Field Manual v2.3 / March 2025, p.2
A31: Adepta Sororitas | C31: Infantry / Other | D31: Infantry | E31: Zephyrim Squad | F31: 5 models | G31: Infantry | L31: 80 | M31: Points options: 5 models = 80 pts; 10 models = 160 pts | N31: Matched to Munitorum Field Manual v2.3 | O31: Uploaded PDF: Munitorum Field Manual v2.3 / March 2025, p.2
A32: Adepta Sororitas | C32: Character | D32: Character | E32: Canoness With Jump Pack | F32: 1 model | G32: Character | L32: 75 | N32: Added from current Munitorum Field Manual v4.1 (non-Legends) | O32: https://www.warhammer-community.com/en-gb/downloads/warhammer-40000/
A33: Adepta Sororitas | C33: Infantry / Other | D33: Infantry | E33: Celestian Insidiants | F33: 10 models | G33: Infantry | L33: 120 | N33: Added from current Munitorum Field Manual v4.1 (non-Legends) | O33: https://www.warhammer-community.com/en-gb/downloads/warhammer-40000/
A34: Adepta Sororitas | C34: Character | D34: Character | E34: Intranzia Fraye | F34: 1 model | G34: Character | L34: 150 | N34: Added from current Munitorum Field Manual v4.1 (non-Legends) | O34: https://www.warhammer-community.com/en-gb/downloads/warhammer-40000/
A35: Adepta Sororitas | C35: Infantry / Other | D35: Infantry | E35: Repentia Squad | F35: 5 models | G35: Infantry | L35: 75 | N35: Added from current Munitorum Field Manual v4.1 (non-Legends) | O35: https://www.warhammer-community.com/en-gb/downloads/warhammer-40000/
A36: Adepta Sororitas | C36: Infantry / Other | D36: Infantry | E36: Sanctifiers | F36: 9 models | G36: Infantry | L36: 110 | N36: Added from current Munitorum Field Manual v4.1 (non-Legends) | O36: https://www.warhammer-community.com/en-gb/downloads/warhammer-40000/
A37: Adepta Sororitas | C37: Infantry / Other | D37: Infantry | E37: Sisters Novitiate Squad | F37: 10 models | G37: Infantry | L37: 100 | N37: Added from current Munitorum Field Manual v4.1 (non-Legends) | O37: https://www.warhammer-community.com/en-gb/downloads/warhammer-40000/

Sheet Adeptus Custodes
A1: Faction | B1: Subfaction/Chapter | C1: Battlefield Role | D1: Unit Type | E1: Unit Name | F1: Models | G1: Keywords / Tags | H1: Owned? | I1: Built? | J1: Paint Status | K1: Wishlist Priority | L1: Points | M1: Notes | N1: Verification Status | O1: Source URL
A2: Adeptus Custodes | C2: Infantry / Other | D2: Infantry | E2: Aleya | F2: 1 model | G2: Infantry | L2: 65 | N2: Matched to Munitorum Field Manual v2.3 | O2: Uploaded PDF: Munitorum Field Manual v2.3 / March 2025, p.3
A3: Adeptus Custodes | C3: Infantry / Other | D3: Infantry | E3: Allarus Custodians | F3: 2 models | G3: Infantry | L3: 130 | M3: Points options: 2 models = 130 pts; 3 models = 195 pts; 5 models = 325 pts; 6 models = 390 pts | N3: Matched to Munitorum Field Manual v2.3 | O3: Uploaded PDF: Munitorum Field Manual v2.3 / March 2025, p.3
A4: Adeptus Custodes | C4: Character | D4: Character | E4: Blade Champion | F4: 1 model | G4: Character | L4: 120 | N4: Matched to Munitorum Field Manual v2.3 | O4: Uploaded PDF: Munitorum Field Manual v2.3 / March 2025, p.3
A5: Adeptus Custodes | C5: Infantry / Other | D5: Infantry | E5: Custodian Guard | F5: 4 models | G5: Infantry | L5: 170 | M5: Points options: 4 models = 170 pts; 5 models = 215 pts | N5: Matched to Munitorum Field Manual v2.3 | O5: Uploaded PDF: Munitorum Field Manual v2.3 / March 2025, p.3
A6: Adeptus Custodes | C6: Infantry / Other | D6: Infantry | E6: Custodian Wardens | F6: 4 models | G6: Infantry | L6: 210 | M6: Points options: 4 models = 210 pts; 5 models = 260 pts | N6: Matched to Munitorum Field Manual v2.3 | O6: Uploaded PDF: Munitorum Field Manual v2.3 / March 2025, p.3
A7: Adeptus Custodes | C7: Vehicle / Support | D7: Super-heavy Vehicle/Monster | E7: Knight-Centura | F7: 1 model | G7: Super-heavy Vehicle/Monster | L7: 55 | N7: Matched to Munitorum Field Manual v2.3 | O7: Uploaded PDF: Munitorum Field Manual v2.3 / March 2025, p.3
A8: Adeptus Custodes | C8: Infantry / Other | D8: Infantry | E8: Prosecutors | F8: 4 models | G8: Infantry | L8: 40 | M8: Points options: 4 models = 40 pts; 5 models = 50 pts; 9 models = 90 pts; 10 models = 100 pts | N8: Matched to Munitorum Field Manual v2.3 | O8: Uploaded PDF: Munitorum Field Manual v2.3 / March 2025, p.3
A9: Adeptus Custodes | C9: Character | D9: Character | E9: Shield-Captain | F9: 1 model | G9: Character | L9: 130 | N9: Matched to Munitorum Field Manual v2.3 | O9: Uploaded PDF: Munitorum Field Manual v2.3 / March 2025, p.3
A10: Adeptus Custodes | C10: Character | D10: Character | E10: Shield-Captain in Allarus Terminator Armour | F10: 1 model | G10: Character | L10: 130 | N10: Matched to Munitorum Field Manual v2.3 | O10: Uploaded PDF: Munitorum Field Manual v2.3 / March 2025, p.3
A11: Adeptus Custodes | C11: Character | D11: Character | E11: Shield-Captain on Dawneagle Jetbike | F11: 1 model | G11: Character | L11: 150 | N11: Matched to Munitorum Field Manual v2.3 | O11: Uploaded PDF: Munitorum Field Manual v2.3 / March 2025, p.3
A12: Adeptus Custodes | C12: Infantry / Other | D12: Infantry | E12: Trajann Valoris | F12: 1 model | G12: Infantry, Epic Hero | L12: 140 | N12: Matched to Munitorum Field Manual v2.3 | O12: Uploaded PDF: Munitorum Field Manual v2.3 / March 2025, p.3
A13: Adeptus Custodes | C13: Infantry / Other | D13: Infantry | E13: Valerian | F13: 1 model | G13: Infantry | L13: 110 | N13: Matched to Munitorum Field Manual v2.3 | O13: Uploaded PDF: Munitorum Field Manual v2.3 / March 2025, p.3
A14: Adeptus Custodes | C14: Infantry / Other | D14: Mounted / Bike | E14: Vertus Praetors | F14: 2 models | G14: Mounted / Bike | L14: 150 | M14: Points options: 2 models = 150 pts; 3 models = 225 pts | N14: Matched to Munitorum Field Manual v2.3 | O14: Uploaded PDF: Munitorum Field Manual v2.3 / March 2025, p.3
A15: Adeptus Custodes | C15: Infantry / Other | D15: Infantry | E15: Vigilators | F15: 4 models | G15: Infantry | L15: 50 | M15: Points options: 4 models = 50 pts; 5 models = 65 pts; 9 models = 115 pts; 10 models = 125 pts | N15: Matched to Munitorum Field Manual v2.3 | O15: Uploaded PDF: Munitorum Field Manual v2.3 / March 2025, p.3
A16: Adeptus Custodes | C16: Infantry / Other | D16: Infantry | E16: Witchseekers | F16: 4 models | G16: Infantry | L16: 50 | M16: Points options: 4 models = 50 pts; 5 models = 65 pts; 9 models = 115 pts; 10 models = 125 pts | N16: Matched to Munitorum Field Manual v2.3 | O16: Uploaded PDF: Munitorum Field Manual v2.3 / March 2025, p.3
A17: Adeptus Custodes | C17: Vehicle / Support | D17: Walker / Battlesuit | E17: Venerable Contemptor Dreadnought | F17: 1 model | G17: Walker / Battlesuit | L17: 170 | N17: Matched to Munitorum Field Manual v2.3 | O17: Uploaded PDF: Munitorum Field Manual v2.3 / March 2025, p.3
A18: Adeptus Custodes | C18: Vehicle / Support | D18: Vehicle | E18: Venerable Land Raider | F18: 1 model | G18: Vehicle | L18: 240 | N18: Matched to Munitorum Field Manual v2.3 | O18: Uploaded PDF: Munitorum Field Manual v2.3 / March 2025, p.3
A19: Adeptus Custodes | C19: Infantry / Other | D19: Infantry | E19: Agamatus Custodians | F19: 3 models | G19: Infantry | L19: 225 | N19: Added from current Munitorum Field Manual v4.1 (non-Legends) | O19: https://www.warhammer-community.com/en-gb/downloads/warhammer-40000/
A20: Adeptus Custodes | C20: Vehicle / Support | D20: Vehicle | E20: Anathema Psykana Rhino | F20: 1 model | G20: Vehicle | L20: 75 | N20: Added from current Munitorum Field Manual v4.1 (non-Legends) | O20: https://www.warhammer-community.com/en-gb/downloads/warhammer-40000/
A21: Adeptus Custodes | C21: Infantry / Other | D21: Infantry | E21: Aquilon Custodians | F21: 3 models | G21: Infantry | L21: 195 | N21: Added from current Munitorum Field Manual v4.1 (non-Legends) | O21: https://www.warhammer-community.com/en-gb/downloads/warhammer-40000/
A22: Adeptus Custodes | C22: Vehicle / Support | D22: Vehicle | E22: Ares Gunship | F22: 1 model | G22: Vehicle | L22: 580 | M22: Your 1st Unit Costs: 1 models = 580 pts | Your 2nd + Unit Costs: 1 models = 610 pts | N22: Added from current Munitorum Field Manual v4.1 (non-Legends) | O22: https://www.warhammer-community.com/en-gb/downloads/warhammer-40000/
A23: Adeptus Custodes | C23: Vehicle / Support | D23: Vehicle | E23: Caladius Grav-Tank | F23: 1 model | G23: Vehicle | L23: 210 | M23: Your 1st To 2nd Units Cost: 1 models = 210 pts | Your 3rd + Unit Costs: 1 models = 225 pts | Wargear: Twin arachnus heavy blaze cannon +15 pts | N23: Added from current Munitorum Field Manual v4.1 (non-Legends) | O23: https://www.warhammer-community.com/en-gb/downloads/warhammer-40000/
A24: Adeptus Custodes | C24: Vehicle / Support | D24: Vehicle | E24: Contemptor-Achillus Dreadnought | F24: 1 model | G24: Vehicle | L24: 155 | M24: Your 1st To 2nd Units Cost: 1 models = 155 pts | Your 3rd + Unit Costs: 1 models = 170 pts | N24: Added from current Munitorum Field Manual v4.1 (non-Legends) | O24: https://www.warhammer-community.com/en-gb/downloads/warhammer-40000/
A25: Adeptus Custodes | C25: Vehicle / Support | D25: Vehicle | E25: Contemptor-Galatus Dreadnought | F25: 1 model | G25: Vehicle | L25: 165 | M25: Your 1st To 2nd Units Cost: 1 models = 165 pts | Your 3rd + Unit Costs: 1 models = 180 pts | N25: Added from current Munitorum Field Manual v4.1 (non-Legends) | O25: https://www.warhammer-community.com/en-gb/downloads/warhammer-40000/
A26: Adeptus Custodes | C26: Vehicle / Support | D26: Vehicle | E26: Coronus Grav-Carrier | F26: 1 model | G26: Vehicle | L26: 180 | M26: Your 1st To 2nd Units Cost: 1 models = 180 pts | Your 3rd + Unit Costs: 1 models = 200 pts | N26: Added from current Munitorum Field Manual v4.1 (non-Legends) | O26: https://www.warhammer-community.com/en-gb/downloads/warhammer-40000/
A27: Adeptus Custodes | C27: Infantry / Other | D27: Infantry | E27: Custodian Guard With Adrasite And Pyrithite Spears | F27: 5 models | G27: Infantry | L27: 250 | M27: Your 1st To 3rd Units Cost: 5 models = 250 pts | Your 4th + Unit Costs: 5 models = 260 pts | N27: Added from current Munitorum Field Manual v4.1 (non-Legends) | O27: https://www.warhammer-community.com/en-gb/downloads/warhammer-40000/
A28: Adeptus Custodes | C28: Vehicle / Support | D28: Vehicle | E28: Orion Assault Dropship | F28: 1 model | G28: Vehicle | L28: 690 | M28: Your 1st Unit Costs: 1 models = 690 pts | Your 2nd + Unit Costs: 1 models = 740 pts | N28: Added from current Munitorum Field Manual v4.1 (non-Legends) | O28: https://www.warhammer-community.com/en-gb/downloads/warhammer-40000/
A29: Adeptus Custodes | C29: Vehicle / Support | D29: Vehicle | E29: Pallas Grav-Attack | F29: 1 model | G29: Vehicle | L29: 100 | N29: Added from current Munitorum Field Manual v4.1 (non-Legends) | O29: https://www.warhammer-community.com/en-gb/downloads/warhammer-40000/
A30: Adeptus Custodes | C30: Infantry / Other | D30: Infantry | E30: Sagittarum Custodians | F30: 5 models | G30: Infantry | L30: 225 | N30: Added from current Munitorum Field Manual v4.1 (non-Legends) | O30: https://www.warhammer-community.com/en-gb/downloads/warhammer-40000/
A31: Adeptus Custodes | C31: Vehicle / Support | D31: Vehicle | E31: Telemon Heavy Dreadnought | F31: 1 model | G31: Vehicle | L31: 225 | M31: Your 1st Unit Costs: 1 models = 225 pts | Your 2nd + Unit Costs: 1 models = 245 pts | N31: Added from current Munitorum Field Manual v4.1 (non-Legends) | O31: https://www.warhammer-community.com/en-gb/downloads/warhammer-40000/
A32: Adeptus Custodes | C32: Infantry / Other | D32: Infantry | E32: Venatari Custodians | F32: 3 models | G32: Infantry | L32: 160 | N32: Added from current Munitorum Field Manual v4.1 (non-Legends) | O32: https://www.warhammer-community.com/en-gb/downloads/warhammer-40000/

Sheet Adeptus Mechanicus
A1: Faction | B1: Subfaction/Chapter | C1: Battlefield Role | D1: Unit Type | E1: Unit Name | F1: Models | G1: Keywords / Tags | H1: Owned? | I1: Built? | J1: Paint Status | K1: Wishlist Priority | L1: Points | M1: Notes | N1: Verification Status | O1: Source URL
A2: Adeptus Mechanicus | C2: Vehicle / Support | D2: Vehicle | E2: Archaeopter Fusilave | F2: 1 model | G2: Vehicle | L2: 160 | N2: Matched to Munitorum Field Manual v2.3 | O2: Uploaded PDF: Munitorum Field Manual v2.3 / March 2025, p.4
A3: Adeptus Mechanicus | C3: Vehicle / Support | D3: Vehicle | E3: Archaeopter Stratoraptor | F3: 1 model | G3: Vehicle | L3: 185 | N3: Matched to Munitorum Field Manual v2.3 | O3: Uploaded PDF: Munitorum Field Manual v2.3 / March 2025, p.4
A4: Adeptus Mechanicus | C4: Vehicle / Support | D4: Vehicle | E4: Archaeopter Transvector | F4: 1 model | G4: Vehicle | L4: 150 | N4: Matched to Munitorum Field Manual v2.3 | O4: Uploaded PDF: Munitorum Field Manual v2.3 / March 2025, p.4
A5: Adeptus Mechanicus | C5: Infantry / Other | D5: Infantry | E5: Belisarius Cawl | F5: 1 model | G5: Infantry | L5: 135 | N5: Matched to Munitorum Field Manual v2.3 | O5: Uploaded PDF: Munitorum Field Manual v2.3 / March 2025, p.4
A6: Adeptus Mechanicus | C6: Character | D6: Character | E6: Corpuscarii Electro-Priests | F6: 5 models | G6: Character | L6: 65 | M6: Points options: 5 models = 65 pts; 10 models = 130 pts | N6: Matched to Munitorum Field Manual v2.3 | O6: Uploaded PDF: Munitorum Field Manual v2.3 / March 2025, p.4
A7: Adeptus Mechanicus | C7: Infantry / Other | D7: Infantry | E7: Cybernetica Datasmith | F7: 1 model | G7: Infantry | L7: 35 | N7: Matched to Munitorum Field Manual v2.3 | O7: Uploaded PDF: Munitorum Field Manual v2.3 / March 2025, p.4
A8: Adeptus Mechanicus | C8: Character | D8: Character | E8: Fulgurite Electro-Priests | F8: 5 models | G8: Character | L8: 70 | M8: Points options: 5 models = 70 pts; 10 models = 140 pts | N8: Matched to Munitorum Field Manual v2.3 | O8: Uploaded PDF: Munitorum Field Manual v2.3 / March 2025, p.4
A9: Adeptus Mechanicus | C9: Vehicle / Support | D9: Walker / Battlesuit | E9: Ironstrider Ballistarii | F9: 1 model | G9: Walker / Battlesuit | L9: 75 | M9: Points options: 1 model = 75 pts; 2 models = 150 pts; 3 models = 225 pts | N9: Matched to Munitorum Field Manual v2.3 | O9: Uploaded PDF: Munitorum Field Manual v2.3 / March 2025, p.4
A10: Adeptus Mechanicus | C10: Vehicle / Support | D10: Walker / Battlesuit | E10: Kastelan Robots | F10: 2 models | G10: Walker / Battlesuit | L10: 180 | M10: Points options: 2 models = 180 pts; 4 models = 360 pts | N10: Matched to Munitorum Field Manual v2.3 | O10: Uploaded PDF: Munitorum Field Manual v2.3 / March 2025, p.4
A11: Adeptus Mechanicus | C11: Infantry / Other | D11: Infantry | E11: Kataphron Breachers | F11: 3 models | G11: Infantry | L11: 160 | M11: Points options: 3 models = 160 pts; 6 models = 320 pts | N11: Matched to Munitorum Field Manual v2.3 | O11: Uploaded PDF: Munitorum Field Manual v2.3 / March 2025, p.4
A12: Adeptus Mechanicus | C12: Infantry / Other | D12: Infantry | E12: Kataphron Destroyers | F12: 3 models | G12: Infantry | L12: 105 | M12: Points options: 3 models = 105 pts; 6 models = 210 pts | N12: Matched to Munitorum Field Manual v2.3 | O12: Uploaded PDF: Munitorum Field Manual v2.3 / March 2025, p.4
A13: Adeptus Mechanicus | C13: Vehicle / Support | D13: Walker / Battlesuit | E13: Onager Dunecrawler | F13: 1 model | G13: Walker / Battlesuit | L13: 155 | N13: Matched to Munitorum Field Manual v2.3 | O13: Uploaded PDF: Munitorum Field Manual v2.3 / March 2025, p.4
A14: Adeptus Mechanicus | C14: Vehicle / Support | D14: Walker / Battlesuit | E14: Pteraxii Skystalkers | F14: 5 models | G14: Walker / Battlesuit | L14: 70 | M14: Points options: 5 models = 70 pts; 10 models = 140 pts | N14: Matched to Munitorum Field Manual v2.3 | O14: Uploaded PDF: Munitorum Field Manual v2.3 / March 2025, p.4
A15: Adeptus Mechanicus | C15: Infantry / Other | D15: Infantry | E15: Pteraxii Sterylizors | F15: 5 models | G15: Infantry | L15: 80 | M15: Points options: 5 models = 80 pts; 10 models = 160 pts | N15: Matched to Munitorum Field Manual v2.3 | O15: Uploaded PDF: Munitorum Field Manual v2.3 / March 2025, p.4
A16: Adeptus Mechanicus | C16: Infantry / Other | D16: Infantry | E16: Secutarii Hoplites | G16: Infantry | M16: No matching points entry found in uploaded PDF; verify unit name/current support. | N16: Not found in uploaded PDF | O16: Uploaded PDF: Munitorum Field Manual v2.3 / March 2025
A17: Adeptus Mechanicus | C17: Infantry / Other | D17: Infantry | E17: Secutarii Peltasts | G17: Infantry | M17: No matching points entry found in uploaded PDF; verify unit name/current support. | N17: Not found in uploaded PDF | O17: Uploaded PDF: Munitorum Field Manual v2.3 / March 2025
A18: Adeptus Mechanicus | C18: Vehicle / Support | D18: Vehicle | E18: Serberys Raiders | F18: 3 models | G18: Vehicle | L18: 60 | M18: Points options: 3 models = 60 pts; 6 models = 120 pts | N18: Matched to Munitorum Field Manual v2.3 | O18: Uploaded PDF: Munitorum Field Manual v2.3 / March 2025, p.4
A19: Adeptus Mechanicus | C19: Infantry / Other | D19: Mounted / Bike | E19: Serberys Sulphurhounds | F19: 3 models | G19: Mounted / Bike | L19: 55 | M19: Points options: 3 models = 55 pts; 6 models = 110 pts | N19: Matched to Munitorum Field Manual v2.3 | O19: Uploaded PDF: Munitorum Field Manual v2.3 / March 2025, p.4
A20: Adeptus Mechanicus | C20: Infantry / Other | D20: Infantry | E20: Sicarian Infiltrators | F20: 5 models | G20: Infantry | L20: 70 | M20: Points options: 5 models = 70 pts; 10 models = 140 pts | N20: Matched to Munitorum Field Manual v2.3 | O20: Uploaded PDF: Munitorum Field Manual v2.3 / March 2025, p.4
A21: Adeptus Mechanicus | C21: Vehicle / Support | D21: Walker / Battlesuit | E21: Sicarian Ruststalkers | F21: 5 models | G21: Walker / Battlesuit | L21: 75 | M21: Points options: 5 models = 75 pts; 10 models = 150 pts | N21: Matched to Munitorum Field Manual v2.3 | O21: Uploaded PDF: Munitorum Field Manual v2.3 / March 2025, p.4
A22: Adeptus Mechanicus | C22: Character | D22: Character | E22: Skitarii Marshal | F22: 1 model | G22: Character | L22: 35 | N22: Matched to Munitorum Field Manual v2.3 | O22: Uploaded PDF: Munitorum Field Manual v2.3 / March 2025, p.4
A23: Adeptus Mechanicus | C23: Infantry / Other | D23: Infantry | E23: Skitarii Rangers | F23: 10 models | G23: Infantry | L23: 85 | N23: Matched to Munitorum Field Manual v2.3 | O23: Uploaded PDF: Munitorum Field Manual v2.3 / March 2025, p.4
A24: Adeptus Mechanicus | C24: Infantry / Other | D24: Infantry | E24: Skitarii Vanguard | F24: 10 models | G24: Infantry | L24: 95 | N24: Matched to Munitorum Field Manual v2.3 | O24: Uploaded PDF: Munitorum Field Manual v2.3 / March 2025, p.4
A25: Adeptus Mechanicus | C25: Vehicle / Support | D25: Vehicle | E25: Skorpius Disintegrator | F25: 1 model | G25: Vehicle | L25: 175 | N25: Matched to Munitorum Field Manual v2.3 | O25: Uploaded PDF: Munitorum Field Manual v2.3 / March 2025, p.4
A26: Adeptus Mechanicus | C26: Vehicle / Support | D26: Vehicle | E26: Skorpius Dunerider | F26: 1 model | G26: Vehicle | L26: 85 | N26: Matched to Munitorum Field Manual v2.3 | O26: Uploaded PDF: Munitorum Field Manual v2.3 / March 2025, p.4
A27: Adeptus Mechanicus | C27: Vehicle / Support | D27: Walker / Battlesuit | E27: Sydonian Dragoons | G27: Walker / Battlesuit | M27: No matching points entry found in uploaded PDF; verify unit name/current support. | N27: Not found in uploaded PDF | O27: Uploaded PDF: Munitorum Field Manual v2.3 / March 2025
A28: Adeptus Mechanicus | C28: Character | D28: Character | E28: Tech-Priest Dominus | F28: 1 model | G28: Character | L28: 65 | N28: Matched to Munitorum Field Manual v2.3 | O28: Uploaded PDF: Munitorum Field Manual v2.3 / March 2025, p.4
A29: Adeptus Mechanicus | C29: Character | D29: Character | E29: Tech-Priest Enginseer | F29: 1 model | G29: Character | L29: 55 | N29: Matched to Munitorum Field Manual v2.3 | O29: Uploaded PDF: Munitorum Field Manual v2.3 / March 2025, p.4
A30: Adeptus Mechanicus | C30: Character | D30: Character | E30: Tech-Priest Manipulus | F30: 1 model | G30: Character | L30: 60 | N30: Matched to Munitorum Field Manual v2.3 | O30: Uploaded PDF: Munitorum Field Manual v2.3 / March 2025, p.4
A31: Adeptus Mechanicus | C31: Infantry / Other | D31: Infantry | E31: Hastarii Exterminators | F31: 5 models | G31: Infantry | L31: 115 | M31: Your 1st To 2nd Units Cost: 5 models = 115 pts | Your 3rd + Unit Costs: 5 models = 130 pts | N31: Added from current Munitorum Field Manual v4.1 (non-Legends) | O31: https://www.warhammer-community.com/en-gb/downloads/warhammer-40000/
A32: Adeptus Mechanicus | C32: Infantry / Other | D32: Infantry | E32: Hastarii Fusiliers | F32: 5 models | G32: Infantry | L32: 115 | M32: Your 1st To 2nd Units Cost: 5 models = 115 pts | Your 3rd + Unit Costs: 5 models = 130 pts | N32: Added from current Munitorum Field Manual v4.1 (non-Legends) | O32: https://www.warhammer-community.com/en-gb/downloads/warhammer-40000/
A33: Adeptus Mechanicus | C33: Infantry / Other | D33: Infantry | E33: Servitor Battleclade | F33: 9 models | G33: Infantry | L33: 65 | N33: Added from current Munitorum Field Manual v4.1 (non-Legends) | O33: https://www.warhammer-community.com/en-gb/downloads/warhammer-40000/
A34: Adeptus Mechanicus | C34: Infantry / Other | D34: Infantry | E34: Sydonian Dragoons With Radium Jezzails | F34: 1 model | G34: Infantry | L34: 55 | N34: Added from current Munitorum Field Manual v4.1 (non-Legends) | O34: https://www.warhammer-community.com/en-gb/downloads/warhammer-40000/
A35: Adeptus Mechanicus | C35: Infantry / Other | D35: Infantry | E35: Sydonian Dragoons With Taser Lances | F35: 1 model | G35: Infantry | L35: 60 | N35: Added from current Munitorum Field Manual v4.1 (non-Legends) | O35: https://www.warhammer-community.com/en-gb/downloads/warhammer-40000/
A36: Adeptus Mechanicus | C36: Infantry / Other | D36: Infantry | E36: Sydonian Skatros | F36: 1 model | G36: Infantry | L36: 50 | N36: Added from current Munitorum Field Manual v4.1 (non-Legends) | O36: https://www.warhammer-community.com/en-gb/downloads/warhammer-40000/
A37: Adeptus Mechanicus | C37: Character | D37: Character | E37: Technoarcheologist | F37: 1 model | G37: Character | L37: 45 | N37: Added from current Munitorum Field Manual v4.1 (non-Legends) | O37: https://www.warhammer-community.com/en-gb/downloads/warhammer-40000/
A38: Adeptus Mechanicus | C38: Character | D38: Character | E38: Thulia Ghuld | F38: 1 model | G38: Character | L38: 180 | N38: Added from current Munitorum Field Manual v4.1 (non-Legends) | O38: https://www.warhammer-community.com/en-gb/downloads/warhammer-40000/

Sheet Aeldari
A1: Faction | B1: Subfaction/Chapter | C1: Battlefield Role | D1: Unit Type | E1: Unit Name | F1: Models | G1: Keywords / Tags | H1: Owned? | I1: Built? | J1: Paint Status | K1: Wishlist Priority | L1: Points | M1: Notes | N1: Verification Status | O1: Source URL
A2: Aeldari | C2: Infantry / Other | D2: Infantry | E2: Asurmen | F2: 1 model | G2: Infantry | L2: 135 | N2: Matched to Munitorum Field Manual v2.3 | O2: Uploaded PDF: Munitorum Field Manual v2.3 / March 2025, p.6
A3: Aeldari | C3: Character | D3: Character | E3: Autarch | F3: 1 model | G3: Character | L3: 75 | N3: Matched to Munitorum Field Manual v2.3 | O3: Uploaded PDF: Munitorum Field Manual v2.3 / March 2025, p.6
A4: Aeldari | C4: Character | D4: Character | E4: Autarch Skyrunner | G4: Character | M4: No matching points entry found in uploaded PDF; verify unit name/current support. | N4: Not found in uploaded PDF | O4: Uploaded PDF: Munitorum Field Manual v2.3 / March 2025
A5: Aeldari | C5: Character | D5: Character | E5: Autarch Wayleaper | F5: 1 model | G5: Character | L5: 80 | N5: Matched to Munitorum Field Manual v2.3 | O5: Uploaded PDF: Munitorum Field Manual v2.3 / March 2025, p.6
A6: Aeldari | C6: Monster / Heavy Support | D6: Monster | E6: Avatar of Khaine | F6: 1 model | G6: Monster, Epic Hero | L6: 300 | N6: Matched to Munitorum Field Manual v2.3 | O6: Uploaded PDF: Munitorum Field Manual v2.3 / March 2025, p.6
A7: Aeldari | C7: Infantry / Other | D7: Infantry | E7: Baharroth | F7: 1 model | G7: Infantry | L7: 115 | N7: Matched to Munitorum Field Manual v2.3 | O7: Uploaded PDF: Munitorum Field Manual v2.3 / March 2025, p.6
A8: Aeldari | C8: Infantry / Other | D8: Mounted / Bike | E8: Corsair Voidreavers | F8: 5 models | G8: Mounted / Bike | L8: 60 | M8: Points options: 5 models = 60 pts; 10 models = 120 pts | N8: Matched to Munitorum Field Manual v2.3 | O8: Uploaded PDF: Munitorum Field Manual v2.3 / March 2025, p.6
A9: Aeldari | C9: Infantry / Other | D9: Infantry | E9: Corsair Voidscarred | F9: 5 models | G9: Infantry | L9: 80 | M9: Points options: 5 models = 80 pts; 10 models = 160 pts | N9: Matched to Munitorum Field Manual v2.3 | O9: Uploaded PDF: Munitorum Field Manual v2.3 / March 2025, p.6
A10: Aeldari | C10: Vehicle / Support | D10: Aircraft | E10: Crimson Hunter | F10: 1 model | G10: Aircraft | L10: 160 | N10: Matched to Munitorum Field Manual v2.3 | O10: Uploaded PDF: Munitorum Field Manual v2.3 / March 2025, p.6
A11: Aeldari | C11: Infantry / Other | D11: Infantry | E11: Dark Reapers | F11: 5 models | G11: Infantry | L11: 90 | M11: Points options: 5 models = 90 pts; 10 models = 195 pts | N11: Matched to Munitorum Field Manual v2.3 | O11: Uploaded PDF: Munitorum Field Manual v2.3 / March 2025, p.6
A12: Aeldari | C12: Infantry / Other | D12: Infantry | E12: Dire Avengers | F12: 5 models | G12: Infantry | L12: 80 | M12: Points options: 5 models = 80 pts; 10 models = 160 pts | N12: Matched to Munitorum Field Manual v2.3 | O12: Uploaded PDF: Munitorum Field Manual v2.3 / March 2025, p.6
A13: Aeldari | C13: Infantry / Other | D13: Infantry | E13: Eldrad Ulthran | F13: 1 model | G13: Infantry | L13: 110 | N13: Matched to Munitorum Field Manual v2.3 | O13: Uploaded PDF: Munitorum Field Manual v2.3 / March 2025, p.6
A14: Aeldari | C14: Vehicle / Support | D14: Vehicle | E14: Falcon | F14: 1 model | G14: Vehicle | L14: 130 | N14: Matched to Munitorum Field Manual v2.3 | O14: Uploaded PDF: Munitorum Field Manual v2.3 / March 2025, p.6
A15: Aeldari | C15: Character | D15: Character | E15: Farseer | F15: 1 model | G15: Character, Psyker | L15: 70 | N15: Matched to Munitorum Field Manual v2.3 | O15: Uploaded PDF: Munitorum Field Manual v2.3 / March 2025, p.6
A16: Aeldari | C16: Character | D16: Character | E16: Farseer Skyrunner | F16: 1 model | G16: Character, Psyker | L16: 80 | N16: Matched to Munitorum Field Manual v2.3 | O16: Uploaded PDF: Munitorum Field Manual v2.3 / March 2025, p.6
A17: Aeldari | C17: Infantry / Other | D17: Infantry | E17: Fire Dragons | F17: 5 models | G17: Infantry | L17: 110 | M17: Points options: 5 models = 110 pts; 10 models = 220 pts | N17: Matched to Munitorum Field Manual v2.3 | O17: Uploaded PDF: Munitorum Field Manual v2.3 / March 2025, p.6
A18: Aeldari | C18: Vehicle / Support | D18: Vehicle | E18: Fire Prism | F18: 1 model | G18: Vehicle | L18: 160 | N18: Matched to Munitorum Field Manual v2.3 | O18: Uploaded PDF: Munitorum Field Manual v2.3 / March 2025, p.6
A19: Aeldari | C19: Infantry / Other | D19: Infantry | E19: Fuegan | F19: 1 model | G19: Infantry | L19: 120 | N19: Matched to Munitorum Field Manual v2.3 | O19: Uploaded PDF: Munitorum Field Manual v2.3 / March 2025, p.6
A20: Aeldari | C20: Battleline / Core | D20: Infantry | E20: Guardian Defenders | F20: 11 models | G20: Infantry | L20: 100 | N20: Matched to Munitorum Field Manual v2.3 | O20: Uploaded PDF: Munitorum Field Manual v2.3 / March 2025, p.6
A21: Aeldari | C21: Vehicle / Support | D21: Aircraft | E21: Hemlock Wraithfighter | F21: 1 model | G21: Aircraft | L21: 155 | N21: Matched to Munitorum Field Manual v2.3 | O21: Uploaded PDF: Munitorum Field Manual v2.3 / March 2025, p.6
A22: Aeldari | C22: Infantry / Other | D22: Infantry | E22: Howling Banshees | F22: 5 models | G22: Infantry | L22: 90 | M22: Points options: 5 models = 90 pts; 10 models = 180 pts | N22: Matched to Munitorum Field Manual v2.3 | O22: Uploaded PDF: Munitorum Field Manual v2.3 / March 2025, p.6
A23: Aeldari | C23: Infantry / Other | D23: Infantry | E23: Illic Nightspear | G23: Infantry | M23: No matching points entry found in uploaded PDF; verify unit name/current support. | N23: Not found in uploaded PDF | O23: Uploaded PDF: Munitorum Field Manual v2.3 / March 2025
A24: Aeldari | C24: Infantry / Other | D24: Infantry | E24: Jain Zar | F24: 1 model | G24: Infantry | L24: 105 | N24: Matched to Munitorum Field Manual v2.3 | O24: Uploaded PDF: Munitorum Field Manual v2.3 / March 2025, p.6
A25: Aeldari | C25: Infantry / Other | D25: Infantry | E25: Karandras | G25: Infantry | M25: No matching points entry found in uploaded PDF; verify unit name/current support. | N25: Not found in uploaded PDF | O25: Uploaded PDF: Munitorum Field Manual v2.3 / March 2025
A26: Aeldari | C26: Infantry / Other | D26: Infantry | E26: Maugan Ra | F26: 1 model | G26: Infantry | L26: 100 | N26: Matched to Munitorum Field Manual v2.3 | O26: Uploaded PDF: Munitorum Field Manual v2.3 / March 2025, p.6
A27: Aeldari | C27: Vehicle / Support | D27: Vehicle | E27: Night Spinner | F27: 1 model | G27: Vehicle | L27: 190 | N27: Matched to Munitorum Field Manual v2.3 | O27: Uploaded PDF: Munitorum Field Manual v2.3 / March 2025, p.6
A28: Aeldari | C28: Infantry / Other | D28: Infantry | E28: Prince Yriel | G28: Infantry | M28: No matching points entry found in uploaded PDF; verify unit name/current support. | N28: Not found in uploaded PDF | O28: Uploaded PDF: Munitorum Field Manual v2.3 / March 2025
A29: Aeldari | C29: Infantry / Other | D29: Infantry | E29: Rangers | F29: 5 models | G29: Infantry | L29: 55 | M29: Points options: 5 models = 55 pts; 10 models = 110 pts | N29: Matched to Munitorum Field Manual v2.3 | O29: Uploaded PDF: Munitorum Field Manual v2.3 / March 2025, p.6
A30: Aeldari | C30: Infantry / Other | D30: Infantry | E30: Shining Spears | F30: 3 models | G30: Infantry | L30: 120 | M30: Points options: 3 models = 120 pts; 6 models = 240 pts | N30: Matched to Munitorum Field Manual v2.3 | O30: Uploaded PDF: Munitorum Field Manual v2.3 / March 2025, p.6
A31: Aeldari | C31: Infantry / Other | D31: Infantry | E31: Shroud Runners | F31: 3 models | G31: Infantry | L31: 80 | M31: Points options: 3 models = 80 pts; 6 models = 160 pts | N31: Matched to Munitorum Field Manual v2.3 | O31: Uploaded PDF: Munitorum Field Manual v2.3 / March 2025, p.6
A32: Aeldari | C32: Infantry / Other | D32: Infantry | E32: Spiritseer | F32: 1 model | G32: Infantry | L32: 65 | N32: Matched to Munitorum Field Manual v2.3 | O32: Uploaded PDF: Munitorum Field Manual v2.3 / March 2025, p.6
A33: Aeldari | C33: Infantry / Other | D33: Infantry | E33: Striking Scorpions | F33: 5 models | G33: Infantry | L33: 85 | M33: Points options: 5 models = 85 pts; 10 models = 150 pts | N33: Matched to Munitorum Field Manual v2.3 | O33: Uploaded PDF: Munitorum Field Manual v2.3 / March 2025, p.6
A34: Aeldari | C34: Infantry / Other | D34: Infantry | E34: Swooping Hawks | F34: 5 models | G34: Infantry | L34: 85 | M34: Points options: 5 models = 85 pts; 10 models = 170 pts | N34: Matched to Munitorum Field Manual v2.3 | O34: Uploaded PDF: Munitorum Field Manual v2.3 / March 2025, p.6
A35: Aeldari | C35: Infantry / Other | D35: Infantry | E35: Support Weapons | F35: 1 model | G35: Infantry | L35: 125 | N35: Matched to Munitorum Field Manual v2.3 | O35: Uploaded PDF: Munitorum Field Manual v2.3 / March 2025, p.6
A36: Aeldari | C36: Infantry / Other | D36: Infantry | E36: The Visarch | F36: 1 model | G36: Infantry | L36: 90 | N36: Matched to Munitorum Field Manual v2.3 | O36: Uploaded PDF: Munitorum Field Manual v2.3 / March 2025, p.7
A37: Aeldari | C37: Monster / Heavy Support | D37: Monster | E37: The Yncarne | F37: 1 model | G37: Monster, Epic Hero | L37: 250 | N37: Matched to Munitorum Field Manual v2.3 | O37: Uploaded PDF: Munitorum Field Manual v2.3 / March 2025, p.7
A38: Aeldari | C38: Infantry / Other | D38: Infantry | E38: Troupe | F38: 5 models | G38: Infantry | L38: 85 | M38: Points options: 5 models = 85 pts; 6 models = 100 pts; 11 models = 190 pts; 12 models = 205 pts | N38: Matched to Munitorum Field Manual v2.3 | O38: Uploaded PDF: Munitorum Field Manual v2.3 / March 2025, p.6
A39: Aeldari | C39: Vehicle / Support | D39: Vehicle | E39: Vypers | F39: 1 model | G39: Vehicle | L39: 65 | M39: Points options: 1 model = 65 pts; 2 models = 130 pts | N39: Matched to Munitorum Field Manual v2.3 | O39: Uploaded PDF: Munitorum Field Manual v2.3 / March 2025, p.6
A40: Aeldari | C40: Vehicle / Support | D40: Vehicle | E40: War Walker | F40: 1 model | G40: Vehicle | L40: 95 | M40: Points options: 1 model = 95 pts; 2 models = 190 pts | N40: Matched to Munitorum Field Manual v2.3 | O40: Uploaded PDF: Munitorum Field Manual v2.3 / March 2025, p.6
...

Sheet Astra Militarum
A1: Faction | B1: Subfaction/Chapter | C1: Battlefield Role | D1: Unit Type | E1: Unit Name | F1: Models | G1: Keywords / Tags | H1: Owned? | I1: Built? | J1: Paint Status | K1: Wishlist Priority | L1: Points | M1: Notes | N1: Verification Status | O1: Source URL
A2: Astra Militarum | C2: Vehicle / Support | D2: Walker / Battlesuit | E2: Armoured Sentinels | F2: 1 model | G2: Walker / Battlesuit | L2: 65 | M2: Points options: 1 model = 65 pts; 2 models = 130 pts | N2: Matched to Munitorum Field Manual v2.3 | O2: Uploaded PDF: Munitorum Field Manual v2.3 / March 2025, p.8
A3: Astra Militarum | C3: Infantry / Other | D3: Mounted / Bike | E3: Attilan Rough Riders | F3: 5 models | G3: Mounted / Bike | L3: 60 | M3: Points options: 5 models = 60 pts; 10 models = 120 pts | N3: Matched to Munitorum Field Manual v2.3 | O3: Uploaded PDF: Munitorum Field Manual v2.3 / March 2025, p.8
A4: Astra Militarum | C4: Vehicle / Support | D4: Super-heavy Vehicle/Monster | E4: Baneblade | F4: 1 model | G4: Super-heavy Vehicle/Monster | L4: 480 | N4: Matched to Munitorum Field Manual v2.3 | O4: Uploaded PDF: Munitorum Field Manual v2.3 / March 2025, p.8
A5: Astra Militarum | C5: Vehicle / Support | D5: Super-heavy Vehicle/Monster | E5: Banehammer | F5: 1 model | G5: Super-heavy Vehicle/Monster | L5: 450 | N5: Matched to Munitorum Field Manual v2.3 | O5: Uploaded PDF: Munitorum Field Manual v2.3 / March 2025, p.8
